# 6.2 异常（panic）与恢复（recover）

如6.1所说，由于Go具有多返回值，可预知的异常都表现为返回一个error（类似Java的checked exception异常）

而当发生了一个程序不能运行的异常时候，则使用panic和recover，（类似Java的runtime exception异常）

panic和recover都是内置方法

```golang
// The panic built-in function stops normal execution of the current
// goroutine. When a function F calls panic, normal execution of F stops
// immediately. Any functions whose execution was deferred by F are run in
// the usual way, and then F returns to its caller. To the caller G, the
// invocation of F then behaves like a call to panic, terminating G's
// execution and running any deferred functions. This continues until all
// functions in the executing goroutine have stopped, in reverse order. At
// that point, the program is terminated and the error condition is reported,
// including the value of the argument to panic. This termination sequence
// is called panicking and can be controlled by the built-in function
// recover.
func panic(v interface{})

// The recover built-in function allows a program to manage behavior of a
// panicking goroutine. Executing a call to recover inside a deferred
// function (but not any function called by it) stops the panicking sequence
// by restoring normal execution and retrieves the error value passed to the
// call of panic. If recover is called outside the deferred function it will
// not stop a panicking sequence. In this case, or when the goroutine is not
// panicking, or if the argument supplied to panic was nil, recover returns
// nil. Thus the return value from recover reports whether the goroutine is
// panicking.
func recover() interface{}

```

## panic的使用

```golang
package main

import (
	"fmt"
)

func test() {
	panic("test panic")
}

func main() {
	test()
	fmt.Println("after call test")
}
// Output
panic: test panic

goroutine 1 [running]:
main.test(...)
	/Users/sagacioushugo/go/src/github.com/sagacioushugo/go-learn-notebook-code/ch06/panic1.go:8
main.main()
	/Users/sagacioushugo/go/src/github.com/sagacioushugo/go-learn-notebook-code/ch06/panic1.go:12 +0x3a

```

发生panic而没有recover，panic会一级一级向上传递直到顶层调用方（这里就是main函数），最后会打印panic的入参以及调用栈，若最后也没有处理panic则终止运行



## recover的使用

```golang
package main

import (
	"fmt"
	"reflect"
)

func test() {
	defer func() {
		if err := recover(); err != nil {
			fmt.Println("test recover:", err)
		}
	}()
	panic("test panic")
}

func test1() {
	panic("test1 panic")
}
func main() {
	defer func() {
		if err := recover(); err != nil {
			fmt.Println("main recover:", reflect.TypeOf(err).Kind(), err)
		}
	}()
	test()
	test1()
}
// Output
test recover: test panic
main recover: string test1 panic
```

recover必须在defer执行的函数中使用（recover写在panic前，此时没有panic，写在panic后，recover代码不可达，panic会立刻终止当前函数代码执行）

需要注意的是：panic的入参和recover的返回值的类型都是interface{}，虽然习惯上通常也写err，但并不是error

在defer中panic，可由下一个要执行的defer进行recover

```golang
package main

import (
	"fmt"
	"reflect"
)

func test() {
	defer func() {
		if err := recover(); err != nil {
			fmt.Println("1 test recover:", err)
		} else {
			fmt.Println("1 recover got ", err)
		}
	}()
	defer func() {
		if err := recover(); err != nil {
			fmt.Println("2 test recover:", err)
		} else {
			fmt.Println("2 recover got ", err)
			panic("panic in defer 2")
		}
	}()
	defer func() {
		if err := recover(); err != nil {
			fmt.Println("3 test recover:", err)
		} else {
			fmt.Println("3 recover got ", err)
		}
	}()
	panic("test panic")
}

func test1() {
	panic("test1 panic")
}
func main() {
	defer func() {
		if err := recover(); err != nil {
			fmt.Println("main recover:", reflect.TypeOf(err).Kind(), err)
		}
	}()
	test()
	test1()

}
// Output
3 test recover: test panic
2 recover got  <nil>
1 test recover: panic in defer 2
main recover: string test1 panic
```

### recover获取堆栈信息

recover一个panic后，返回值只是当时panic的入参，想要获取没处理panic时会打出的堆栈信息，需要使用runtime/debug包的PrintStack函数

```golang
package main

import (
	"fmt"
	"runtime/debug"
)

func test() {
	defer func() {
		if r := recover(); r != nil {
			fmt.Println("Recovered", r)
			debug.PrintStack()
		}
	}()
	panic("test panic")
}

func main() {
	test()
	fmt.Println("after call test")
}
// Output
Recovered test panic
goroutine 1 [running]:
after call test
runtime/debug.Stack(0x15, 0x0, 0x0)
	/usr/local/Cellar/go/1.12/libexec/src/runtime/debug/stack.go:24 +0x9d
runtime/debug.PrintStack()
	/usr/local/Cellar/go/1.12/libexec/src/runtime/debug/stack.go:16 +0x22
main.test.func1()
	/Users/sagacioushugo/go/src/github.com/sagacioushugo/go-learn-notebook-code/ch06/panic3.go:12 +0xb5
panic(0x10a38e0, 0x10ddfc0)
	/usr/local/Cellar/go/1.12/libexec/src/runtime/panic.go:522 +0x1b5
main.test()
	/Users/sagacioushugo/go/src/github.com/sagacioushugo/go-learn-notebook-code/ch06/panic3.go:15 +0x55
main.main()
	/Users/sagacioushugo/go/src/github.com/sagacioushugo/go-learn-notebook-code/ch06/panic3.go:19 +0x22
```

## panic、recover和goroutine

recover只会恢复同一个goroutine中的panic，假如一个goroutine的panic没处理直接导致该goroutine终止，那么全部goroutine都会终止，程序停止运行


同协程可recover
```golang
package main

import "fmt"

func divide(a, b int) int {
	fmt.Printf("divide run %d / %d\n", a, b)
	return a / b
}

func main() {
	defer func() {
		if err := recover(); err != nil {
			fmt.Println("Recovered", err)
		}
	}()
	divide(10, 0)
	fmt.Println("main end")
}
// Output
divide run 10 / 0
Recovered runtime error: integer divide by zero
```

不同协程不可recover，子协程panic，父协程直接终止
```golang
package main

import (
	"fmt"
	"time"
)

func divide(a, b int) int {
	fmt.Printf("divide run %d / %d\n", a, b)
	return a / b
}

func main() {
	defer func() {
		if err := recover(); err != nil {
			fmt.Println("Recovered", err)
		}
	}()
	go divide(10, 0)
	time.Sleep(5 * time.Second)
	fmt.Println("main end")
}
// Output
panic: runtime error: integer divide by zero

goroutine 18 [running]:
main.divide(0xa, 0x0, 0xc000062058)
	/Users/sagacioushugo/go/src/github.com/sagacioushugo/go-learn-notebook-code/ch06/panic4.go:10 +0x114
created by main.main
	/Users/sagacioushugo/go/src/github.com/sagacioushugo/go-learn-notebook-code/ch06/panic4.go:19 +0x6b
divide run 10 / 0
```
## 参考资料
https://studygolang.com/articles/12785 Go 系列教程 —— 32. panic 和 recover

https://segmentfault.com/a/1190000019251478 深入理解 Go panic and recover 煎鱼的清汤锅